<?xml version="1.0"?>
<robot xmlns:xacro="http://www.ros.org/wiki/xacro">

  
  <!-- ===================== Wheel Cylinder intertia xacro =============================
  Xacro with the intertial block of a cylinder. For more detail information and usage, see:
    https://github.com/pxalcantara/mobile_robot_description/wiki/Inertia-xacro
  params:
  - m [float]: link mass;
  - r [float]: cylinder radius (radius of wheel);
  - l [float]: cylinder length (width of wheel);
  - prefix [string]: left or right
  - suffix [string]: front or back
  - reflectfrontback [int]: 1(front) or -1(back)
  - reflectside [int]: 1(left) or -1(right)
  -->

    <xacro:macro name="wheel" params="prefix suffix reflectfrontback reflectside m r l">
        <link name="${prefix}_${suffix}_wheel">
        <visual>
            <origin xyz="0 0 0" rpy="${pi/2} 0 0" />
            <geometry>
            <cylinder radius="${r}" length="${l}"/>
            </geometry>
            <material name="black"/>
        </visual>
        <collision>
            <origin xyz="0 0 0" rpy="${pi/2} 0 0" />
            <geometry>
            <cylinder radius="${r}" length="${l}"/>
            </geometry>
        </collision>
        <xacro:cylinder_inertia m="${m}" r="${r}" l="${l}" 
        o_xyz="0.0 0.0 0.0" o_rpy="0.0 0.0 0.0"
        />
        </link>
        <joint name="${prefix}_${suffix}_wheel_joint" type="continuous">
        <axis xyz="0 1 0" rpy="0 0 0" />
        <parent link="base_link"/>
        <child link="${prefix}_${suffix}_wheel"/>
        <origin xyz="${baselen*reflectfrontback/3} ${((basewidth/2)+l/2)*reflectside} ${-r}" rpy="0 0 0"/>
        </joint>


            <!-- This block provides the simulator (Gazebo) with information on a few additional
        physical properties. See http://gazebosim.org/tutorials/?tut=ros_urdf for more-->
        <gazebo reference="${prefix}_${suffix}_wheel">
        <mu1 value="200.0"/>
        <mu2 value="100.0"/>
        <kp value="10000000.0" />
        <kd value="1.0" />
        <material>Gazebo/Grey</material>
        </gazebo>

        <!-- This block connects the wheel joint to an actuator (motor), which informs both
        simulation and visualization of the robot -->
        <transmission name="${prefix}_${suffix}_wheel_trans">
        <type>transmission_interface/SimpleTransmission</type>
        <actuator name="${prefix}_${suffix}_wheel_motor">
            <mechanicalReduction>1</mechanicalReduction>
        </actuator>
        <joint name="${prefix}_${suffix}_wheel_joint">
            <hardwareInterface>VelocityJointInterface</hardwareInterface>
        </joint>
        </transmission>
    </xacro:macro>

  <!-- ======================= Intertial macros ===============================-->
  <!-- ===================== Cylinder intertia xacro =============================
  Xacro with the intertial block of a cylinder. For more detail information and usage, see:
    https://github.com/pxalcantara/mobile_robot_description/wiki/Inertia-xacro
  params:
  - m [float]: link mass;
  - r [float]: cylinder radius;
  - l [float]: cylinder lenght (height);
  -->
  <xacro:macro name="cylinder_inertia" params="m r l o_xyz:='0.0 0.0 0.0' o_rpy:='0.0 0.0 0.0'">
    <inertial>
      <mass value="${m}"/>
      <inertia ixx="${m*(3*r*r+l*l)/12}" ixy = "0" ixz = "0" 
               iyy="${m*(3*r*r+l*l)/12}" iyz = "0" izz="${m*r*r/2}"/>
      <origin xyz="${o_xyz}" rpy="${o_rpy}" />
    </inertial>
  </xacro:macro>


  <!-- ===================== Box intertia xacro ==================================
  Xacro with the intertial block of a box. For more detail information and usage, see:
    https://github.com/pxalcantara/mobile_robot_description/wiki/Inertia-xacro
  params:
  - m [float]: link mass;
  - x [float]: link dimension on the X-axis;
  - y [float]: link dimension on the Y-axis;
  - z [float]: link dimension on the Z-axis;
-->  

<xacro:macro name="base_inertia" params="m x y z o_xyz:='0.0 0.0 0.0' o_rpy:='0.0 0.0 0.0'">
    <inertial>
      <mass value="${m}"/>
      <inertia ixx="${m / 12.0 * (y*y + z*z)}" ixy="0.0" ixz="0.0"
               iyy="${m / 12.0 * (x*x + z*z)}" iyz="0.0" 
               izz="${m / 12.0 * (x*x + y*y)}"/>
      <origin xyz="${o_xyz}" rpy="${o_rpy}" />
    </inertial>
  </xacro:macro>

<!-- ========================================================================-->

<!-- ===================== Material ============================================
  RVIZ material RGBA definition.
-->

  <material name="blue">
    <color rgba="0 0 0.8 1"/>
  </material>
  <material name="black">
    <color rgba="0 0 0 1"/>
  </material>
  <material name="white">
    <color rgba="1 1 1 1"/>
  </material>
  <material name="red">
    <color rgba="0.8 0.0 0.0 1.0"/>
  </material>
  <material name="silver">
    <color rgba="0.79 0.82 0.93 1"/>
  </material>
  <material name="dark_grey">
    <color rgba="0.3 0.3 0.3 1"/>
  </material>
<!-- ========================================================================-->




</robot>